<?xml version="1.0"?>
<robot name="planar_3R">

  <!-- link0 -->
  <link name="link0">
    <inertial>
      <origin xyz="0 0 0" rpy="0 0 0"/>
      <mass value="1.0"/>
      <inertia ixx="0.01" iyy="0.01" izz="0.01" ixy="0" ixz="0" iyz="0"/>
    </inertial>
  </link>

  <!-- joint1 -->
  <joint name="joint1" type="revolute">
    <origin xyz="0 0 0" rpy="0 0 0"/>
    <axis xyz="1 0 0"/>
    <parent link="link0"/>
    <child link="link1"/>
    <limit lower="-3.14" upper="3.14" effort="50" velocity="2.0"/>
  </joint>

  <!-- link1 -->
  <link name="link1">
    <inertial>
      <origin xyz="0 0 0.5" rpy="0 0 0"/>
      <mass value="1.0"/>
      <inertia ixx="0.01" iyy="0.01" izz="0.01" ixy="0" ixz="0" iyz="0"/>
    </inertial>
    <visual>
      <origin xyz="0 0 0.5" rpy="0 0 0"/>
      <geometry>
        <box size="0.1 0.1 1.0"/>
      </geometry>
      <material name="blue">
        <color rgba="0.0 0.0 1.0 1.0"/>
      </material>
    </visual>
  </link>

  <!-- joint2 -->
  <joint name="joint2" type="revolute">
    <origin xyz="0 0 1.0" rpy="0 0 0"/>
    <axis xyz="1 0 0"/>
    <parent link="link1"/>
    <child link="link2"/>
    <limit lower="-3.14" upper="3.14" effort="50" velocity="2.0"/>
  </joint>

  <!-- link2 -->
  <link name="link2">
    <inertial>
      <origin xyz="0 0 0.5" rpy="0 0 0"/>
      <mass value="1.0"/>
      <inertia ixx="0.01" iyy="0.01" izz="0.01" ixy="0" ixz="0" iyz="0"/>
    </inertial>
    <visual>
      <origin xyz="0 0 0.5" rpy="0 0 0"/>
      <geometry>
        <box size="0.1 0.1 1.0"/>
      </geometry>
      <material name="green">
        <color rgba="0.0 1.0 0.0 1.0"/>
      </material>
    </visual>
  </link>

  <!-- joint3 -->
  <joint name="joint3" type="revolute">
    <origin xyz="0 0 1.0" rpy="0 0 0"/>
    <axis xyz="1 0 0"/>
    <parent link="link2"/>
    <child link="link3"/>
    <limit lower="-3.14" upper="3.14" effort="50" velocity="2.0"/>
  </joint>

  <!-- link3 -->
  <link name="link3">
    <inertial>
      <origin xyz="0 0 0.5" rpy="0 0 0"/>
      <mass value="1.0"/>
      <inertia ixx="0.01" iyy="0.01" izz="0.01" ixy="0" ixz="0" iyz="0"/>
    </inertial>
    <visual>
      <origin xyz="0 0 0.5" rpy="0 0 0"/>
      <geometry>
        <box size="0.1 0.1 1.0"/>
      </geometry>
      <material name="red">
        <color rgba="1.0 0.0 0.0 1.0"/>
      </material>
    </visual>
  </link>

  <!-- end-effector frame-->
  <joint name="ee_fixed" type="fixed">
    <origin xyz="0 0 1.0" rpy="0 0 0"/>
    <parent link="link3"/>
    <child link="end_effector"/>
  </joint>

  <link name="end_effector"/>

</robot>